
#######################################################################
# +-----------------------------------------------------------------+ #
# |                            BO3 object                           | #
# +-----------------------------------------------------------------+ #
#######################################################################

Author: NLBlackEagle

Description: Converted version of the BO2 NA15S

Version: 3

SettingsMode: WriteDisable


#######################################################################
# +-----------------------------------------------------------------+ #
# |                          Main settings                          | #
# +-----------------------------------------------------------------+ #
#######################################################################

Tree: true

Frequency: 1

Rarity: 100.0

RotateRandomly: true

SpawnHeight: highestSolidBlock

SpawnHeightOffset: 0

SpawnHeightVariance: 0

##############################
# Height Limits for the BO3. #
##############################

MinHeight: 0

MaxHeight: 199

######################
# Extrusion settings #
######################

ExtrudeMode: None

ExtrudeThroughBlocks: minecraft:air

MaxBranchDepth: 10

ExcludedBiomes: 


#######################################################################
# +-----------------------------------------------------------------+ #
# |                      Source block settings                      | #
# +-----------------------------------------------------------------+ #
#######################################################################

SourceBlocks: minecraft:air

MaxPercentageOutsideSourceBlock: 20

OutsideSourceBlock: placeAnyway


#######################################################################
# +-----------------------------------------------------------------+ #
# |                              Blocks                             | #
# +-----------------------------------------------------------------+ #
#######################################################################

Block(-1,2,2,natura:overworld_leaves2:3)
Block(2,6,0,natura:overworld_leaves2:3)
Block(1,3,-1,natura:overworld_leaves2:3)
Block(1,5,-2,natura:overworld_leaves2:3)
Block(0,2,0,natura:overworld_logs2:3)
Block(-2,4,1,natura:overworld_leaves2:3)
Block(1,3,-2,natura:overworld_leaves2:3)
Block(0,3,0,natura:overworld_logs2:3)
Block(1,5,-1,natura:overworld_leaves2:3)
Block(0,0,0,natura:overworld_logs2:3)
Block(1,6,-1,natura:overworld_leaves2:3)
Block(0,1,0,natura:overworld_logs2:3)
Block(0,6,0,natura:overworld_leaves2:3)
Block(-2,3,0,natura:overworld_leaves2:3)
Block(-1,3,1,natura:overworld_leaves2:3)
Block(0,7,0,natura:overworld_leaves2:3)
Block(-1,4,1,natura:overworld_leaves2:3)
Block(-2,4,0,natura:overworld_leaves2:3)
Block(-2,5,0,natura:overworld_leaves2:3)
Block(0,4,0,natura:overworld_logs2:3)
Block(-1,6,1,natura:overworld_leaves2:3)
Block(0,5,0,natura:overworld_logs2:3)
Block(1,5,1,natura:overworld_leaves2:3)
Block(1,4,1,natura:overworld_leaves2:3)
Block(-2,2,0,natura:overworld_leaves2:3)
Block(-1,1,1,natura:overworld_leaves2:3)
Block(1,2,1,natura:overworld_leaves2:3)
Block(-1,4,-2,natura:overworld_leaves2:3)
Block(1,5,0,natura:overworld_leaves2:3)
Block(1,3,0,natura:overworld_leaves2:3)
Block(1,4,0,natura:overworld_leaves2:3)
Block(0,3,2,natura:overworld_leaves2:3)
Block(0,4,2,natura:overworld_leaves2:3)
Block(-1,3,0,natura:overworld_leaves2:3)
Block(-1,6,0,natura:overworld_leaves2:3)
Block(0,2,1,natura:overworld_leaves2:3)
Block(-1,7,0,natura:overworld_leaves2:3)
Block(0,4,1,natura:overworld_leaves2:3)
Block(0,3,1,natura:overworld_leaves2:3)
Block(0,5,1,natura:overworld_leaves2:3)
Block(0,3,-1,natura:overworld_leaves2:3)
Block(0,7,-1,natura:overworld_leaves2:3)
Block(0,6,-1,natura:overworld_leaves2:3)
Block(0,5,-1,natura:overworld_leaves2:3)
Block(0,4,-1,natura:overworld_leaves2:3)
Block(1,6,1,natura:overworld_leaves2:3)
Block(0,2,-2,natura:overworld_leaves2:3)
Block(1,2,2,natura:overworld_leaves2:3)
Block(1,3,2,natura:overworld_leaves2:3)
Block(2,4,1,natura:overworld_leaves2:3)
Block(-2,4,-1,natura:overworld_leaves2:3)
Block(1,7,0,natura:overworld_leaves2:3)
Block(2,3,1,natura:overworld_leaves2:3)
Block(0,4,-2,natura:overworld_leaves2:3)
Block(0,5,-2,natura:overworld_leaves2:3)
Block(0,6,-2,natura:overworld_leaves2:3)
Block(-1,3,-1,natura:overworld_leaves2:3)
Block(2,3,-1,natura:overworld_leaves2:3)
Block(-1,7,-1,natura:overworld_leaves2:3)
Block(2,2,-1,natura:overworld_leaves2:3)
Block(-1,4,-1,natura:overworld_leaves2:3)
Block(-1,5,-1,natura:overworld_leaves2:3)
Block(2,4,-1,natura:overworld_leaves2:3)
Block(2,2,0,natura:overworld_leaves2:3)
Block(0,7,1,natura:overworld_leaves2:3)
Block(2,6,-1,natura:overworld_leaves2:3)
Block(2,4,0,natura:overworld_leaves2:3)
Block(2,5,0,natura:overworld_leaves2:3)

#######################################################################
# +-----------------------------------------------------------------+ #
# |                            BO3 checks                           | #
# +-----------------------------------------------------------------+ #
#######################################################################

BlockCheck(0,-1,0,minecraft:grass,minecraft:dirt)

#######################################################################
# +-----------------------------------------------------------------+ #
# |                             Branches                            | #
# +-----------------------------------------------------------------+ #
#######################################################################

